El manejo de errores es una parte crucial de la programación reactiva con Observables. RxJS proporciona varios operadores para gestionar errores de manera efectiva.

#### `catchError`

El operador `catchError` intercepta un error emitido por un Observable y devuelve un nuevo Observable o lanza un nuevo error.

```ad-info
title: catchError
```
```
import { of, throwError } from 'rxjs';
import { catchError } from 'rxjs/operators';

const observableWithError = throwError('An error occurred');

const handledObservable = observableWithError.pipe(
  catchError(error => {
    console.error(error);
    return of('Fallback value');
  })
);

handledObservable.subscribe(value => console.log(value));
```

Salida

```
An error occurred
Fallback value
```

#### `retry`

El operador `retry` reintenta la suscripción a un Observable un número específico de veces cuando se produce un error.

```ad-info
title: retry
```
```
import { of, throwError } from 'rxjs';
import { catchError, retry } from 'rxjs/operators';

const observableWithError = throwError('An error occurred');

const retriedObservable = observableWithError.pipe(
  retry(3),
  catchError(error => {
    console.error(error);
    return of('Fallback value');
  })
);

retriedObservable.subscribe(value => console.log(value));
```

Salida

```
An error occurred
An error occurred
An error occurred
An error occurred
Fallback value
```

#### `retryWhen`

El operador `retryWhen` reintenta la suscripción a un Observable basado en un Observable de notificación de error. Esto permite implementar lógica de reintento personalizada.

```ad-info
title: retryWhen
```
```
import { of, throwError, timer } from 'rxjs';
import { catchError, retryWhen, delayWhen } from 'rxjs/operators';

const observableWithError = throwError('An error occurred');

const retriedWithDelayObservable = observableWithError.pipe(
  retryWhen(errors =>
    errors.pipe(
      delayWhen(() => timer(2000))
    )
  ),
  catchError(error => {
    console.error(error);
    return of('Fallback value');
  })
);

retriedWithDelayObservable.subscribe(value => console.log(value));
```

Salida

```
An error occurred
(Fallback value después de 2 segundos)
```

